Workbook

Sheet 0-使用说明
A1: 双色球投注方案生成工具 - 使用说明
A2: 版本：1.0 | 创建日期：2026-01-04
A4: 📋 完整工作流程
A6: 步骤1 | B6: 数据输入 | C6: 在【1-数据输入】表中输入最近30期开奖数据（红球1-6+蓝球）
A7: 步骤2 | B7: 24码分析 | C7: 系统自动分析生成24码主流区间（【2-24码分析】表）
A8: 步骤3 | B8: 方案生成 | C8: 基于24码自动生成8-12注投注方案（【3-投注方案】表）
A9: 步骤4 | B9: 投注执行 | C9: 按生成的方案进行投注
A10: 步骤5 | B10: 开奖录入 | C10: 在【4-开奖结果】表中输入开奖号码
A11: 步骤6 | B11: 中奖判断 | C11: 系统自动判断中奖情况并更新【5-历史记录】表
A12: 步骤7 | B12: 查看分析 | C12: 在【6-统计分析】表查看中奖统计和效率分析
A15: ✨ 核心功能特点
A17: • 全自动化：输入数据后所有分析、方案生成、中奖判断全部自动完成
A18: • 智能24码：基于最近30期数据动态计算热门号码区间
A19: • 双模板策略：80%使用模板A（3奇3偶），20%使用模板B（2奇4偶）
A20: • 结构优化：自动控制连号、同尾数量，提高中奖概率
A21: • 历史追踪：完整保存所有投注和中奖历史
A22: • 数据分析：多维度统计分析，包括中奖率、ROI、号码热度等
A25: ⚠️ 重要注意事项
A27: 1. 必须输入完整的最近30期数据，数据不足会影响分析准确性
A28: 2. 红球范围01-33，蓝球范围01-16，输入时注意范围
A29: 3. 每期建议生成8-12注，不超过15注
A30: 4. 投注方案仅供参考，不保证中奖
... A52: 如有问题或建议，请联系开发团队

Sheet 1-数据输入
A1: 双色球历史数据输入表
A2: 说明：请输入最近30期开奖数据，系统将自动计算24码主流区间并生成投注方案
A4: 期号 | B4: 红球1 | C4: 红球2 | D4: 红球3 | E4: 红球4 | F4: 红球5 | G4: 红球6 | H4: 蓝球
A5: 2025001 | B5: 2 | C5: 3 | D5: 17 | E5: 18 | F5: 22 | G5: 33 | H5: 8
A6: 2025002 | B6: 5 | C6: 8 | D6: 12 | E6: 19 | F6: 26 | G6: 30 | H6: 11
A7: 2025003 | B7: 1 | C7: 7 | D7: 14 | E7: 21 | F7: 28 | G7: 32 | H7: 6
A8: 2025004 | B8: 4 | C8: 9 | D8: 15 | E8: 20 | F8: 25 | G8: 31 | H8: 13
A9: 2025005 | B9: 6 | C9: 10 | D9: 16 | E9: 23 | F9: 27 | G9: 29 | H9: 9
A36: 注意事项：
A37: 1. 期号格式：YYYYNNN（如2025001）
A38: 2. 红球范围：01-33（输入时可省略前导零）
A39: 3. 蓝球范围：01-16
A40: 4. 请按时间顺序从旧到新输入最近30期数据

Sheet 2-24码分析
A1: 24码主流区间自动分析
A2: 基于最近30期数据自动计算，取出现频次最高的前24个红球号码
A4: 红球号码 | B4: 出现次数 | C4: 出现频率 | D4: 是否入选 | E4: 排名 | G4: 24码主流区间
A5: 01 | B5: =COUNTIF('1-数据输入'!B5:G34,A5) | C5: =B5/30 | D5: =IF(E5<=24,"✓","") | E5: =RANK(B5,B$5:B$37,0) | G5: =IFERROR(INDEX(A$5:A$37,MATCH(SMALL(E$5:E$37,1),E$5:E$37,0)),"")
A6: 02 | B6: =COUNTIF('1-数据输入'!B5:G34,A6) | C6: =B6/30 | D6: =IF(E6<=24,"✓","") | E6: =RANK(B6,B$5:B$37,0) | G6: =IFERROR(INDEX(A$5:A$37,MATCH(SMALL(E$5:E$37,2),E$5:E$37,0)),"")
A7: 03 | B7: =COUNTIF('1-数据输入'!B5:G34,A7) | C7: =B7/30 | D7: =IF(E7<=24,"✓","") | E7: =RANK(B7,B$5:B$37,0) | G7: =IFERROR(INDEX(A$5:A$37,MATCH(SMALL(E$5:E$37,3),E$5:E$37,0)),"")
A8: 04 | B8: =COUNTIF('1-数据输入'!B5:G34,A8) | C8: =B8/30 | D8: =IF(E8<=24,"✓","") | E8: =RANK(B8,B$5:B$37,0) | G8: =IFERROR(INDEX(A$5:A$37,MATCH(SMALL(E$5:E$37,4),E$5:E$37,0)),"")
A9: 05 | B9: =COUNTIF('1-数据输入'!B5:G34,A9) | C9: =B9/30 | D9: =IF(E9<=24,"✓","") | E9: =RANK(B9,B$5:B$37,0) | G9: =IFERROR(INDEX(A$5:A$37,MATCH(SMALL(E$5:E$37,5),E$5:E$37,0)),"")
A10: 06 | B10: =COUNTIF('1-数据输入'!B5:G34,A10) | C10: =B10/30 | D10: =IF(E10<=24,"✓","") | E10: =RANK(B10,B$5:B$37,0) | G10: =IFERROR(INDEX(A$5:A$37,MATCH(SMALL(E$5:E$37,6),E$5:E$37,0)),"")
A11: 07 | B11: =COUNTIF('1-数据输入'!B5:G34,A11) | C11: =B11/30 | D11: =IF(E11<=24,"✓","") | E11: =RANK(B11,B$5:B$37,0) | G11: =IFERROR(INDEX(A$5:A$37,MATCH(SMALL(E$5:E$37,7),E$5:E$37,0)),"")
A12: 08 | B12: =COUNTIF('1-数据输入'!B5:G34,A12) | C12: =B12/30 | D12: =IF(E12<=24,"✓","") | E12: =RANK(B12,B$5:B$37,0) | G12: =IFERROR(INDEX(A$5:A$37,MATCH(SMALL(E$5:E$37,8),E$5:E$37,0)),"")
A13: 09 | B13: =COUNTIF('1-数据输入'!B5:G34,A13) | C13: =B13/30 | D13: =IF(E13<=24,"✓","") | E13: =RANK(B13,B$5:B$37,0) | G13: =IFERROR(INDEX(A$5:A$37,MATCH(SMALL(E$5:E$37,9),E$5:E$37,0)),"")
A14: 10 | B14: =COUNTIF('1-数据输入'!B5:G34,A14) | C14: =B14/30 | D14: =IF(E14<=24,"✓","") | E14: =RANK(B14,B$5:B$37,0) | G14: =IFERROR(INDEX(A$5:A$37,MATCH(SMALL(E$5:E$37,10),E$5:E$37,0)),"")
A15: 11 | B15: =COUNTIF('1-数据输入'!B5:G34,A15) | C15: =B15/30 | D15: =IF(E15<=24,"✓","") | E15: =RANK(B15,B$5:B$37,0) | G15: =IFERROR(INDEX(A$5:A$37,MATCH(SMALL(E$5:E$37,11),E$5:E$37,0)),"")
A16: 12 | B16: =COUNTIF('1-数据输入'!B5:G34,A16) | C16: =B16/30 | D16: =IF(E16<=24,"✓","") | E16: =RANK(B16,B$5:B$37,0) | G16: =IFERROR(INDEX(A$5:A$37,MATCH(SMALL(E$5:E$37,12),E$5:E$37,0)),"")
A17: 13 | B17: =COUNTIF('1-数据输入'!B5:G34,A17) | C17: =B17/30 | D17: =IF(E17<=24,"✓","") | E17: =RANK(B17,B$5:B$37,0) | G17: =IFERROR(INDEX(A$5:A$37,MATCH(SMALL(E$5:E$37,13),E$5:E$37,0)),"")
A18: 14 | B18: =COUNTIF('1-数据输入'!B5:G34,A18) | C18: =B18/30 | D18: =IF(E18<=24,"✓","") | E18: =RANK(B18,B$5:B$37,0) | G18: =IFERROR(INDEX(A$5:A$37,MATCH(SMALL(E$5:E$37,14),E$5:E$37,0)),"")
A19: 15 | B19: =COUNTIF('1-数据输入'!B5:G34,A19) | C19: =B19/30 | D19: =IF(E19<=24,"✓","") | E19: =RANK(B19,B$5:B$37,0) | G19: =IFERROR(INDEX(A$5:A$37,MATCH(SMALL(E$5:E$37,15),E$5:E$37,0)),"")
A20: 16 | B20: =COUNTIF('1-数据输入'!B5:G34,A20) | C20: =B20/30 | D20: =IF(E20<=24,"✓","") | E20: =RANK(B20,B$5:B$37,0) | G20: =IFERROR(INDEX(A$5:A$37,MATCH(SMALL(E$5:E$37,16),E$5:E$37,0)),"")
A21: 17 | B21: =COUNTIF('1-数据输入'!B5:G34,A21) | C21: =B21/30 | D21: =IF(E21<=24,"✓","") | E21: =RANK(B21,B$5:B$37,0) | G21: =IFERROR(INDEX(A$5:A$37,MATCH(SMALL(E$5:E$37,17),E$5:E$37,0)),"")
A22: 18 | B22: =COUNTIF('1-数据输入'!B5:G34,A22) | C22: =B22/30 | D22: =IF(E22<=24,"✓","") | E22: =RANK(B22,B$5:B$37,0) | G22: =IFERROR(INDEX(A$5:A$37,MATCH(SMALL(E$5:E$37,18),E$5:E$37,0)),"")
A23: 19 | B23: =COUNTIF('1-数据输入'!B5:G34,A23) | C23: =B23/30 | D23: =IF(E23<=24,"✓","") | E23: =RANK(B23,B$5:B$37,0) | G23: =IFERROR(INDEX(A$5:A$37,MATCH(SMALL(E$5:E$37,19),E$5:E$37,0)),"")
A24: 20 | B24: =COUNTIF('1-数据输入'!B5:G34,A24) | C24: =B24/30 | D24: =IF(E24<=24,"✓","") | E24: =RANK(B24,B$5:B$37,0) | G24: =IFERROR(INDEX(A$5:A$37,MATCH(SMALL(E$5:E$37,20),E$5:E$37,0)),"")
A25: 21 | B25: =COUNTIF('1-数据输入'!B5:G34,A25) | C25: =B25/30 | D25: =IF(E25<=24,"✓","") | E25: =RANK(B25,B$5:B$37,0) | G25: =IFERROR(INDEX(A$5:A$37,MATCH(SMALL(E$5:E$37,21),E$5:E$37,0)),"")
A26: 22 | B26: =COUNTIF('1-数据输入'!B5:G34,A26) | C26: =B26/30 | D26: =IF(E26<=24,"✓","") | E26: =RANK(B26,B$5:B$37,0) | G26: =IFERROR(INDEX(A$5:A$37,MATCH(SMALL(E$5:E$37,22),E$5:E$37,0)),"")
A27: 23 | B27: =COUNTIF('1-数据输入'!B5:G34,A27) | C27: =B27/30 | D27: =IF(E27<=24,"✓","") | E27: =RANK(B27,B$5:B$37,0) | G27: =IFERROR(INDEX(A$5:A$37,MATCH(SMALL(E$5:E$37,23),E$5:E$37,0)),"")
A28: 24 | B28: =COUNTIF('1-数据输入'!B5:G34,A28) | C28: =B28/30 | D28: =IF(E28<=24,"✓","") | E28: =RANK(B28,B$5:B$37,0) | G28: =IFERROR(INDEX(A$5:A$37,MATCH(SMALL(E$5:E$37,24),E$5:E$37,0)),"")
A29: 25 | B29: =COUNTIF('1-数据输入'!B5:G34,A29) | C29: =B29/30 | D29: =IF(E29<=24,"✓","") | E29: =RANK(B29,B$5:B$37,0)
A30: 26 | B30: =COUNTIF('1-数据输入'!B5:G34,A30) | C30: =B30/30 | D30: =IF(E30<=24,"✓","") | E30: =RANK(B30,B$5:B$37,0)
A31: 27 | B31: =COUNTIF('1-数据输入'!B5:G34,A31) | C31: =B31/30 | D31: =IF(E31<=24,"✓","") | E31: =RANK(B31,B$5:B$37,0)
A32: 28 | B32: =COUNTIF('1-数据输入'!B5:G34,A32) | C32: =B32/30 | D32: =IF(E32<=24,"✓","") | E32: =RANK(B32,B$5:B$37,0)
A33: 29 | B33: =COUNTIF('1-数据输入'!B5:G34,A33) | C33: =B33/30 | D33: =IF(E33<=24,"✓","") | E33: =RANK(B33,B$5:B$37,0)
A34: 30 | B34: =COUNTIF('1-数据输入'!B5:G34,A34) | C34: =B34/30 | D34: =IF(E34<=24,"✓","") | E34: =RANK(B34,B$5:B$37,0)
A35: 31 | B35: =COUNTIF('1-数据输入'!B5:G34,A35) | C35: =B35/30 | D35: =IF(E35<=24,"✓","") | E35: =RANK(B35,B$5:B$37,0)
A36: 32 | B36: =COUNTIF('1-数据输入'!B5:G34,A36) | C36: =B36/30 | D36: =IF(E36<=24,"✓","") | E36: =RANK(B36,B$5:B$37,0)
A37: 33 | B37: =COUNTIF('1-数据输入'!B5:G34,A37) | C37: =B37/30 | D37: =IF(E37<=24,"✓","") | E37: =RANK(B37,B$5:B$37,0)

Sheet 3-投注方案
A1: 自动生成投注方案
A2: 基于24码自动生成8-12注投注方案，80%使用模板A，20%使用模板B
A4: 模板A（80%）： | B4: 3奇3偶 + 3小3大 + 连号≤1组 + 同尾≤1组
A5: 模板B（20%）： | B5: 2奇4偶 + 2小4大 + 连号≤1组 + 同尾≤2组
A7: 期号 | B7: 注号 | C7: 模板 | D7: 红球1 | E7: 红球2 | F7: 红球3 | G7: 红球4 | H7: 红球5 | I7: 红球6 | J7: 蓝球 | L7: 方案生成指引
A8: ='1-数据输入'!A5 | B8: 1 | C8: A | D8: ='2-24码分析'!G$7 | L8: 1. 获取当期24码
A9: ='1-数据输入'!A5 | B9: 2 | C9: A | D9: ='2-24码分析'!G$9 | L9: 2. 生成8-12注方案
A10: ='1-数据输入'!A5 | B10: 3 | C10: A | D10: ='2-24码分析'!G$11 | L10: 3. 随机分配模板A/B
A11: ='1-数据输入'!A5 | B11: 4 | C11: A | D11: ='2-24码分析'!G$13 | L11: 4. 验证结构要求
A12: ='1-数据输入'!A5 | B12: 5 | C12: A | D12: ='2-24码分析'!G$15 | L12: 5. 自动填充蓝球
A13: ='1-数据输入'!A5 | B13: 6 | C13: A | D13: ='2-24码分析'!G$17
A14: ='1-数据输入'!A5 | B14: 7 | C14: A | D14: ='2-24码分析'!G$19
A15: ='1-数据输入'!A5 | B15: 8 | C15: A | D15: ='2-24码分析'!G$21
A16: ='1-数据输入'!A5 | B16: 9 | C16: B | D16: ='2-24码分析'!G$23
A17: ='1-数据输入'!A5 | B17: 10 | C17: B | D17: ='2-24码分析'!G$25
A18: ='1-数据输入'!A6 | B18: 1 | C18: A | D18: ='2-24码分析'!G$7
A19: ='1-数据输入'!A6 | B19: 2 | C19: A | D19: ='2-24码分析'!G$9
A20: ='1-数据输入'!A6 | B20: 3 | C20: A | D20: ='2-24码分析'!G$11
A21: ='1-数据输入'!A6 | B21: 4 | C21: A | D21: ='2-24码分析'!G$13
A22: ='1-数据输入'!A6 | B22: 5 | C22: A | D22: ='2-24码分析'!G$15
A23: ='1-数据输入'!A6 | B23: 6 | C23: A | D23: ='2-24码分析'!G$17
A24: ='1-数据输入'!A6 | B24: 7 | C24: A | D24: ='2-24码分析'!G$19
A25: ='1-数据输入'!A6 | B25: 8 | C25: A | D25: ='2-24码分析'!G$21
A26: ='1-数据输入'!A6 | B26: 9 | C26: B | D26: ='2-24码分析'!G$23
A27: ='1-数据输入'!A6 | B27: 10 | C27: B | D27: ='2-24码分析'!G$25
A28: ='1-数据输入'!A7 | B28: 1 | C28: A | D28: ='2-24码分析'!G$7
A29: ='1-数据输入'!A7 | B29: 2 | C29: A | D29: ='2-24码分析'!G$9
A30: ='1-数据输入'!A7 | B30: 3 | C30: A | D30: ='2-24码分析'!G$11
A31: ='1-数据输入'!A7 | B31: 4 | C31: A | D31: ='2-24码分析'!G$13
A32: ='1-数据输入'!A7 | B32: 5 | C32: A | D32: ='2-24码分析'!G$15
A33: ='1-数据输入'!A7 | B33: 6 | C33: A | D33: ='2-24码分析'!G$17
A34: ='1-数据输入'!A7 | B34: 7 | C34: A | D34: ='2-24码分析'!G$19
A35: ='1-数据输入'!A7 | B35: 8 | C35: A | D35: ='2-24码分析'!G$21
A36: ='1-数据输入'!A7 | B36: 9 | C36: B | D36: ='2-24码分析'!G$23
A37: ='1-数据输入'!A7 | B37: 10 | C37: B | D37: ='2-24码分析'!G$25
A38: ='1-数据输入'!A8 | B38: 1 | C38: A | D38: ='2-24码分析'!G$7
A39: ='1-数据输入'!A8 | B39: 2 | C39: A | D39: ='2-24码分析'!G$9
A40: ='1-数据输入'!A8 | B40: 3 | C40: A | D40: ='2-24码分析'!G$11
A41: ='1-数据输入'!A8 | B41: 4 | C41: A | D41: ='2-24码分析'!G$13
A42: ='1-数据输入'!A8 | B42: 5 | C42: A | D42: ='2-24码分析'!G$15
...

Sheet 4-开奖结果
A1: 开奖结果输入与中奖判断
A2: 输入开奖号码后，系统自动判断中奖情况
A4: 期号 | B4: 开奖红球1 | C4: 红球2 | D4: 红球3 | E4: 红球4 | F4: 红球5 | G4: 红球6 | H4: 开奖蓝球 | I4: 录入时间
A5: ='1-数据输入'!A5
A6: ='1-数据输入'!A6
A7: ='1-数据输入'!A7
A8: ='1-数据输入'!A8
A9: ='1-数据输入'!A9
A10: ='1-数据输入'!A10
A11: ='1-数据输入'!A11
A12: ='1-数据输入'!A12
A13: ='1-数据输入'!A13
A14: ='1-数据输入'!A14
A15: ='1-数据输入'!A15
A16: ='1-数据输入'!A16
... A54: ='1-数据输入'!A54

Sheet 5-历史记录
A1: 投注与中奖历史记录
A3: 期号 | B3: 注号 | C3: 投注红球 | D3: 投注蓝球 | E3: 开奖红球 | F3: 开奖蓝球 | G3: 中红球数 | H3: 中蓝球 | I3: 中奖等级 | J3: 奖金 | K3: 投入 | L3: 盈亏 | M3: 备注 | O3: 中奖等级说明
O4: 一等奖 | P4: 6+1
O5: 二等奖 | P5: 6+0
O6: 三等奖 | P6: 5+1
O7: 四等奖 | P7: 5+0 / 4+1
O8: 五等奖 | P8: 4+0 / 3+1
O9: 六等奖 | P9: 2+1 / 1+1 / 0+1

Sheet 6-统计分析
A1: 数据统计与分析报告
A3: 总体统计 | D3: 中奖等级分布 | F3: 24码热度TOP10
A4: 总投注期数 | B4: =COUNTA('5-历史记录'!A4:A503) | D4: 一等奖 | E4: =COUNTIF('5-历史记录'!I4:I503,D4) | F4: 排名 | G4: 号码 | H4: 出现次数
A5: 总投注注数 | B5: =COUNTA('5-历史记录'!B4:B503) | D5: 二等奖 | E5: =COUNTIF('5-历史记录'!I4:I503,D5) | F5: 1 | G5: ='2-24码分析'!G5 | H5: ='2-24码分析'!B5
A6: 总投入金额 | B6: =SUM('5-历史记录'!K4:K503) | D6: 三等奖 | E6: =COUNTIF('5-历史记录'!I4:I503,D6) | F6: 2 | G6: ='2-24码分析'!G6 | H6: ='2-24码分析'!B6
A7: 总中奖注数 | B7: =COUNTIF('5-历史记录'!I4:I503,"<>") | D7: 四等奖 | E7: =COUNTIF('5-历史记录'!I4:I503,D7) | F7: 3 | G7: ='2-24码分析'!G7 | H7: ='2-24码分析'!B7
A8: 总奖金 | B8: =SUM('5-历史记录'!J4:J503) | D8: 五等奖 | E8: =COUNTIF('5-历史记录'!I4:I503,D8) | F8: 4 | G8: ='2-24码分析'!G8 | H8: ='2-24码分析'!B8
A9: 总盈亏 | B9: =SUM('5-历史记录'!L4:L503) | D9: 六等奖 | E9: =COUNTIF('5-历史记录'!I4:I503,D9) | F9: 5 | G9: ='2-24码分析'!G9 | H9: ='2-24码分析'!B9
A10: 中奖率 | B10: =B7/B5 | F10: 6 | G10: ='2-24码分析'!G10 | H10: ='2-24码分析'!B10
A11: 投资回报率 | B11: =B8/B6 | F11: 7 | G11: ='2-24码分析'!G11 | H11: ='2-24码分析'!B11
F12: 8 | G12: ='2-24码分析'!G12 | H12: ='2-24码分析'!B12
A13: 模板效率对比 | F13: 9 | G13: ='2-24码分析'!G13 | H13: ='2-24码分析'!B13
A14: 模板 | B14: 使用次数 | C14: 中奖次数 | D14: 中奖率 | F14: 10 | G14: ='2-24码分析'!G14 | H14: ='2-24码分析'!B14
A15: 模板A
A16: 模板B
